# [코틀린의 예외 처리]

```kotlin
if (percentage !in 0..100) {
    throw IllegalArgumentException(
        "A percentage vale must bge between 0 and 100: $percentage"
    )
}
```

```kotlin
val percentage=
    if (number in 0..100) number
    else throw IllegalArgumentException(
        "A percentage vale must bge between 0 and 100: $number"
    )
```

- if의 조건이 참 -> `percentage` 값이 `number`로 초기화
- if의 조건이 거짓 -> 초기화 X

## 1. try, catch, finally

```kotlin
import java.io.BufferedReader
import java.lang.NumberFormatException

fun readNumber(reader: BufferedReader): Int? {
    try {
        val line = reader.readLine()
        return line.toInt()
    } catch (e: NumberFormatException){
        return null
    } finally {
        reader.close()
    }
}
```

- Java와 다르게 `throws`절이 코드에 없다.
- Java는 `throws IOException` 구문이 필요하다.
  - `IOException`이 체크 예외(checked exception)이기 때문
  - Java는 체크 예외를 명시적으로 처리해야 함
- Java는 어떤 함수가 던질 가능성이 있는 예외나 그 함수가 호출한 다른 함수에서 발생할 수 있는 예외를 모두 `catch`로 처리해야 한다.
- 처리하지 않은 예외는`throws`절에 명시해야 한다.
- Kotlin도 체크 예외와 언체크 예외를 구별하지 않는다.
  - 함수가 던지는 예외를 지정하지 않고 발생한 예외를 잡아도 되고, 안잡아도 된다.
  - Java는 체크 예외 처리를 강제한다.
- 위에서 사용한 `NumberFormatException`은 체크 예외가 아니다. -> Java Compiler는 이를 잡아내게 강제하지 않는다.
  - 클라이언트에게서 발생할 경우를 고려하여 예외 처리를 해주어야 한다.
- `BufferedReader.close()`는 `IOException`을 던질 수 있다. -> 체크 예외가 아니므로 Java에서는 반드시 처리해야 한다.
  - 하지만 실제 스트림을 닫다가 실패하는 경우는 클라이언트에게서 벌어질 수 없다.
  - 따라서 해당 `IOException`을 잡는 동작은 무의미하다.

---

## 2. try를 식으로 사용

```kotlin
import java.io.BufferedReader
import java.lang.NumberFormatException

fun readNumber(reader: BufferedReader) {
    val number = try {
        Integer.parseInt(reader.readLine())
    } catch (e: NumberFormatException) {
        retrun
    }
    println(number)
}
```

- kotlin의 `try` 키워드는 **식**이다.
- 따라서 `try`의 값을 변수에 대입할 수 있다.
- 예외 발생의 경우 `return`문을 사용하여 다음 코드를 실행하지 않는다.